Traceback (most recent call last):
  File "C:\Users\USUARIO\Documents\DataViz2024-1\dataVizz-Jbook\.venv\Lib\site-packages\jupyter_cache\executors\utils.py", line 58, in single_nb_execution
    executenb(
  File "C:\Users\USUARIO\Documents\DataViz2024-1\dataVizz-Jbook\.venv\Lib\site-packages\nbclient\client.py", line 1314, in execute
    return NotebookClient(nb=nb, resources=resources, km=km, **kwargs).execute()
           ^^^^^^^^^^^^^^^^^^^^^^^^^^^^^^^^^^^^^^^^^^^^^^^^^^^^^^^^^^^^^^^^^^^^^
  File "C:\Users\USUARIO\Documents\DataViz2024-1\dataVizz-Jbook\.venv\Lib\site-packages\jupyter_core\utils\__init__.py", line 165, in wrapped
    return loop.run_until_complete(inner)
           ^^^^^^^^^^^^^^^^^^^^^^^^^^^^^^
  File "C:\Program Files\WindowsApps\PythonSoftwareFoundation.Python.3.11_3.11.2544.0_x64__qbz5n2kfra8p0\Lib\asyncio\base_events.py", line 654, in run_until_complete
    return future.result()
           ^^^^^^^^^^^^^^^
  File "C:\Users\USUARIO\Documents\DataViz2024-1\dataVizz-Jbook\.venv\Lib\site-packages\nbclient\client.py", line 709, in async_execute
    await self.async_execute_cell(
  File "C:\Users\USUARIO\Documents\DataViz2024-1\dataVizz-Jbook\.venv\Lib\site-packages\nbclient\client.py", line 1062, in async_execute_cell
    await self._check_raise_for_error(cell, cell_index, exec_reply)
  File "C:\Users\USUARIO\Documents\DataViz2024-1\dataVizz-Jbook\.venv\Lib\site-packages\nbclient\client.py", line 918, in _check_raise_for_error
    raise CellExecutionError.from_cell_and_msg(cell, exec_reply_content)
nbclient.exceptions.CellExecutionError: An error occurred while executing the following cell:
------------------
from sklearn.experimental import enable_iterative_imputer
from sklearn.impute import SimpleImputer, IterativeImputer
import pandas as pd
import numpy as np
from sklearn.model_selection import train_test_split
from sklearn.metrics import accuracy_score
from sklearn.tree import DecisionTreeClassifier
from sklearn.linear_model import LogisticRegression
from sklearn.ensemble import RandomForestClassifier
import matplotlib.pyplot as plt
from scipy.stats import zscore, t
import seaborn as sns
import matplotlib.pyplot as plt
from sklearn.model_selection import cross_val_score
from sklearn.pipeline import make_pipeline
from sklearn.preprocessing import StandardScaler
from sklearn.ensemble import HistGradientBoostingClassifier, StackingClassifier, BaggingClassifier, VotingClassifier
import ssl
ssl._create_default_https_context = ssl._create_unverified_context
------------------


[1;31m---------------------------------------------------------------------------[0m
[1;31mModuleNotFoundError[0m                       Traceback (most recent call last)
Cell [1;32mIn[1], line 1[0m
[1;32m----> 1[0m [38;5;28;01mfrom[39;00m [38;5;21;01msklearn[39;00m[38;5;21;01m.[39;00m[38;5;21;01mexperimental[39;00m [38;5;28;01mimport[39;00m enable_iterative_imputer
[0;32m      2[0m [38;5;28;01mfrom[39;00m [38;5;21;01msklearn[39;00m[38;5;21;01m.[39;00m[38;5;21;01mimpute[39;00m [38;5;28;01mimport[39;00m SimpleImputer, IterativeImputer
[0;32m      3[0m [38;5;28;01mimport[39;00m [38;5;21;01mpandas[39;00m [38;5;28;01mas[39;00m [38;5;21;01mpd[39;00m

[1;31mModuleNotFoundError[0m: No module named 'sklearn'

