Traceback (most recent call last):
  File "C:\Users\USUARIO\Documents\DataViz2024-1\dataVizz-Jbook\.venv\Lib\site-packages\jupyter_cache\executors\utils.py", line 58, in single_nb_execution
    executenb(
  File "C:\Users\USUARIO\Documents\DataViz2024-1\dataVizz-Jbook\.venv\Lib\site-packages\nbclient\client.py", line 1314, in execute
    return NotebookClient(nb=nb, resources=resources, km=km, **kwargs).execute()
           ^^^^^^^^^^^^^^^^^^^^^^^^^^^^^^^^^^^^^^^^^^^^^^^^^^^^^^^^^^^^^^^^^^^^^
  File "C:\Users\USUARIO\Documents\DataViz2024-1\dataVizz-Jbook\.venv\Lib\site-packages\jupyter_core\utils\__init__.py", line 165, in wrapped
    return loop.run_until_complete(inner)
           ^^^^^^^^^^^^^^^^^^^^^^^^^^^^^^
  File "C:\Program Files\WindowsApps\PythonSoftwareFoundation.Python.3.11_3.11.2544.0_x64__qbz5n2kfra8p0\Lib\asyncio\base_events.py", line 654, in run_until_complete
    return future.result()
           ^^^^^^^^^^^^^^^
  File "C:\Users\USUARIO\Documents\DataViz2024-1\dataVizz-Jbook\.venv\Lib\site-packages\nbclient\client.py", line 709, in async_execute
    await self.async_execute_cell(
  File "C:\Users\USUARIO\Documents\DataViz2024-1\dataVizz-Jbook\.venv\Lib\site-packages\nbclient\client.py", line 1062, in async_execute_cell
    await self._check_raise_for_error(cell, cell_index, exec_reply)
  File "C:\Users\USUARIO\Documents\DataViz2024-1\dataVizz-Jbook\.venv\Lib\site-packages\nbclient\client.py", line 918, in _check_raise_for_error
    raise CellExecutionError.from_cell_and_msg(cell, exec_reply_content)
nbclient.exceptions.CellExecutionError: An error occurred while executing the following cell:
------------------
import warnings
from yahoo_fin.stock_info import get_data
warnings.filterwarnings("ignore")
import yfinance as yf
from datetime import datetime, timedelta
import seaborn as sns
import matplotlib.pyplot as plt
import plotly.graph_objects as go
from statsmodels.tsa.stattools import adfuller
from numpy import log
import numpy as np, pandas as pd
from statsmodels.graphics.tsaplots import plot_acf, plot_pacf
from statsmodels.tsa.arima.model import ARIMA
import pmdarima as pm
from statsmodels.graphics.tsaplots import plot_predict
from sklearn.metrics import r2_score
import statsmodels.api as sm
from statsmodels.stats.diagnostic import acorr_ljungbox
from sklearn.metrics import mean_absolute_error, mean_squared_error, mean_absolute_percentage_error, r2_score



------------------


[1;31m---------------------------------------------------------------------------[0m
[1;31mModuleNotFoundError[0m                       Traceback (most recent call last)
Cell [1;32mIn[1], line 2[0m
[0;32m      1[0m [38;5;28;01mimport[39;00m [38;5;21;01mwarnings[39;00m
[1;32m----> 2[0m [38;5;28;01mfrom[39;00m [38;5;21;01myahoo_fin[39;00m[38;5;21;01m.[39;00m[38;5;21;01mstock_info[39;00m [38;5;28;01mimport[39;00m get_data
[0;32m      3[0m warnings[38;5;241m.[39mfilterwarnings([38;5;124m"[39m[38;5;124mignore[39m[38;5;124m"[39m)
[0;32m      4[0m [38;5;28;01mimport[39;00m [38;5;21;01myfinance[39;00m [38;5;28;01mas[39;00m [38;5;21;01myf[39;00m

[1;31mModuleNotFoundError[0m: No module named 'yahoo_fin'

